Workbook

Sheet נתוני_תשלומים
A1: מספר דירה | B1: גודל דירה | C1: סכום חודשי (₪) | D1: פעיל | E1: חוב עד 12/25 (₪) | F1: ינואר 25 | G1: פברואר 25 | H1: מרץ 25 | I1: אפריל 25 | J1: מאי 25 | K1: יוני 25 | L1: יולי 25 | M1: אוגוסט 25 | N1: ספטמבר 25 | O1: אוקטובר 25 | P1: נובמבר 25 | Q1: דצמבר 25 | R1: ינואר 26 | S1: פברואר 26 | T1: מרץ 26 | U1: אפריל 26 | V1: מאי 26 | W1: יוני 26 | X1: יולי 26 | Y1: אוגוסט 26 | Z1: ספטמבר 26 | AA1: אוקטובר 26 | AB1: נובמבר 26 | AC1: דצמבר 26
A2: 1 | B2: 5 חדרים | C2: 554 | D2: 1 | E2: 810 | H2: 2 | I2: 2 | J2: 2 | K2: 2 | L2: 2 | M2: 2 | N2: 2 | O2: 2 | R2: 0 | S2: 0 | T2: 0
A3: 2 | B3: 5 חדרים | C3: 522 | D3: 1 | E3: 0 | H3: 2 | I3: 2 | J3: 2 | K3: 2 | L3: 2 | M3: 2 | N3: 2 | O3: 2 | P3: 2 | Q3: 2 | R3: 2 | S3: 2 | T3: 0
A4: 3 | B4: 5 חדרים | C4: 549 | D4: 1 | E4: 0 | H4: 2 | I4: 2 | J4: 2 | K4: 2 | L4: 2 | M4: 2 | N4: 2 | O4: 2 | P4: 2 | Q4: 2 | R4: 2 | S4: 2 | T4: 0
A5: 4 | B5: 5 חדרים | C5: 549 | D5: 1 | E5: 0 | H5: 2 | I5: 2 | J5: 2 | K5: 2 | L5: 2 | M5: 2 | N5: 2 | O5: 2 | P5: 2 | Q5: 2 | R5: 2 | S5: 2 | T5: 1 | U5: 1 | V5: 1 | W5: 1 | X5: 1 | Y5: 1 | Z5: 1 | AA5: 1 | AB5: 1 | AC5: 1
A6: 5 | B6: 4 חדרים | C6: 482 | D6: 1 | E6: 0 | H6: 2 | I6: 2 | J6: 2 | K6: 2 | L6: 2 | M6: 2 | N6: 2 | O6: 2 | P6: 2 | Q6: 2 | R6: 2 | S6: 2 | T6: 1 | U6: 1 | V6: 1 | W6: 1
A7: 6 | B7: 3 חדרים | C7: 347 | D7: 1 | E7: 0 | H7: 2 | I7: 2 | J7: 2 | K7: 2 | L7: 2 | M7: 2 | N7: 2 | O7: 2 | P7: 2 | Q7: 2 | R7: 2 | S7: 2 | T7: 2
A8: 7 | B8: 3 חדרים | C8: 347 | D8: 1 | E8: 0 | H8: 2 | I8: 2 | J8: 2 | K8: 2 | L8: 2 | M8: 2 | N8: 2 | O8: 2 | P8: 2 | Q8: 2 | R8: 2 | S8: 2 | T8: 0
A9: 8 | B9: 5 חדרים | C9: 522 | D9: 1 | E9: 0 | H9: 2 | I9: 2 | J9: 2 | K9: 2 | L9: 2 | M9: 2 | N9: 2 | O9: 2 | P9: 2 | Q9: 2 | R9: 2 | S9: 2 | T9: 0
A10: 9 | B10: 5 חדרים | C10: 549 | D10: 1 | E10: 0 | H10: 2 | I10: 2 | J10: 2 | K10: 2 | L10: 2 | M10: 2 | N10: 2 | O10: 2 | P10: 2 | Q10: 2 | R10: 2 | S10: 2 | T10: 0
A11: 10 | B11: 5 חדרים | C11: 549 | D11: 1 | E11: 0 | H11: 2 | I11: 2 | J11: 2 | K11: 2 | L11: 2 | M11: 2 | N11: 2 | O11: 2 | P11: 2 | Q11: 2 | R11: 2 | S11: 2 | T11: 1 | U11: 1 | V11: 1 | W11: 1 | X11: 1 | Y11: 1 | Z11: 1 | AA11: 1 | AB11: 1 | AC11: 1
A12: 11 | B12: 4 חדרים | C12: 482 | D12: 1 | E12: 0 | H12: 2 | I12: 2 | J12: 2 | K12: 2 | L12: 2 | M12: 2 | N12: 2 | O12: 2 | P12: 2 | Q12: 2 | R12: 2 | S12: 2 | T12: 0
A13: 12 | B13: 3 חדרים | C13: 347 | D13: 1 | E13: 0 | H13: 2 | I13: 2 | J13: 2 | K13: 2 | L13: 2 | M13: 2 | N13: 2 | O13: 2 | P13: 2 | Q13: 2 | R13: 2 | S13: 2 | T13: 0
A14: 13 | B14: 3 חדרים | C14: 347 | D14: 1 | E14: 0 | H14: 2 | I14: 2 | J14: 2 | K14: 2 | L14: 2 | M14: 2 | N14: 2 | O14: 2 | P14: 2 | Q14: 2 | R14: 2 | S14: 2 | T14: 0
A15: 14 | B15: 5 חדרים | C15: 522 | D15: 1 | E15: 0 | H15: 2 | I15: 2 | J15: 2 | K15: 2 | L15: 2 | M15: 2 | N15: 2 | O15: 2 | P15: 2 | Q15: 2 | R15: 2 | S15: 2 | T15: 1 | U15: 1 | V15: 1 | W15: 1 | X15: 1 | Y15: 1 | Z15: 1 | AA15: 1 | AB15: 1 | AC15: 1
A16: 15 | B16: 5 חדרים | C16: 549 | D16: 1 | E16: 0 | H16: 2 | I16: 2 | J16: 2 | K16: 2 | L16: 2 | M16: 2 | N16: 2 | O16: 2 | P16: 2 | Q16: 2 | R16: 2 | S16: 2 | T16: 1 | U16: 1 | V16: 1 | W16: 1 | X16: 1 | Y16: 1 | Z16: 1 | AA16: 1 | AB16: 1 | AC16: 1
A17: 16 | B17: 5 חדרים | C17: 549 | D17: 1 | E17: 0 | H17: 2 | I17: 2 | J17: 2 | K17: 2 | L17: 2 | M17: 2 | N17: 2 | O17: 2 | P17: 2 | Q17: 2 | R17: 0 | S17: 0 | T17: 0
A18: 17 | B18: 4 חדרים | C18: 482 | D18: 1 | E18: 482 | H18: 2 | I18: 2 | J18: 2 | K18: 2 | L18: 2 | M18: 2 | N18: 2 | O18: 2 | P18: 2 | R18: 2 | S18: 2 | T18: 0
A19: 18 | B19: 3 חדרים | C19: 347 | D19: 1 | E19: 0 | H19: 2 | I19: 2 | J19: 2 | K19: 2 | L19: 2 | M19: 2 | N19: 2 | O19: 2 | P19: 2 | Q19: 2 | R19: 2 | S19: 0 | T19: 0
A20: 19 | B20: 3 חדרים | C20: 347 | D20: 1 | E20: 0 | H20: 2 | I20: 2 | J20: 2 | K20: 2 | L20: 2 | M20: 2 | N20: 2 | O20: 2 | P20: 2 | Q20: 2 | R20: 2 | S20: 2 | T20: 0
A21: 20 | B21: 5 חדרים | C21: 522 | D21: 1 | E21: 0 | H21: 2 | I21: 2 | J21: 2 | K21: 2 | L21: 2 | M21: 2 | N21: 2 | O21: 2 | P21: 2 | Q21: 2 | R21: 2 | S21: 2 | T21: 1 | U21: 1 | V21: 1 | W21: 1 | X21: 1 | Y21: 1 | Z21: 1 | AB21: 1 | AC21: 1
A22: 21 | B22: 5 חדרים | C22: 549 | D22: 1 | E22: 0 | H22: 2 | I22: 2 | J22: 2 | K22: 2 | L22: 2 | M22: 2 | N22: 2 | O22: 2 | P22: 2 | Q22: 2 | R22: 2 | S22: 2 | T22: 0
A23: 22 | B23: 5 חדרים | C23: 549 | D23: 1 | E23: 0 | H23: 2 | I23: 2 | J23: 2 | K23: 2 | L23: 2 | M23: 2 | N23: 2 | O23: 2 | P23: 2 | Q23: 2 | R23: 2 | S23: 2 | T23: 0
A24: 23 | B24: 4 חדרים | C24: 482 | D24: 1 | E24: 0 | H24: 2 | I24: 2 | J24: 2 | K24: 2 | L24: 2 | M24: 2 | N24: 2 | O24: 2 | P24: 2 | Q24: 2 | R24: 2 | S24: 2 | T24: 1 | U24: 1 | V24: 1 | W24: 1 | X24: 1 | Y24: 1 | Z24: 1 | AA24: 1 | AB24: 1 | AC24: 1
A25: 24 | B25: 3 חדרים | C25: 347 | D25: 1 | E25: 0 | H25: 2 | I25: 2 | J25: 2 | K25: 2 | L25: 2 | M25: 2 | N25: 2 | O25: 2 | P25: 2 | Q25: 2 | R25: 2 | S25: 2 | T25: 0
A26: 25 | B26: 3 חדרים | C26: 347 | D26: 1 | E26: 0 | H26: 2 | I26: 2 | J26: 2 | K26: 2 | L26: 2 | M26: 2 | N26: 2 | O26: 2 | P26: 2 | Q26: 2 | R26: 2 | S26: 2 | T26: 0
A27: 26 | B27: 5 חדרים | C27: 522 | D27: 1 | E27: 0 | H27: 2 | I27: 2 | J27: 2 | K27: 2 | L27: 2 | M27: 2 | N27: 2 | O27: 2 | P27: 2 | Q27: 2 | R27: 2 | S27: 2 | T27: 1 | U27: 1 | V27: 1 | W27: 1 | X27: 1 | Y27: 1 | Z27: 1 | AA27: 1 | AB27: 1 | AC27: 1
A28: 27 | B28: 5 חדרים | C28: 549 | D28: 1 | E28: 0 | H28: 2 | I28: 2 | J28: 2 | K28: 2 | L28: 2 | M28: 2 | N28: 2 | O28: 2 | P28: 2 | Q28: 2 | R28: 0 | S28: 0 | T28: 0
A29: 28 | B29: 5 חדרים | C29: 549 | D29: 0 | E29: 0
A30: 29 | B30: 4 חדרים | C30: 482 | D30: 1 | E30: 0 | H30: 2 | I30: 2 | J30: 2 | K30: 2 | L30: 2 | M30: 2 | N30: 2 | O30: 2 | P30: 2 | Q30: 2 | R30: 2 | S30: 2 | T30: 1 | U30: 1 | V30: 1 | W30: 1 | X30: 1 | Y30: 1 | Z30: 1 | AA30: 1 | AB30: 1 | AC30: 1
A31: 30 | B31: 3 חדרים | C31: 347 | D31: 1 | E31: 5287 | R31: 0 | S31: 0 | T31: 0
A32: 31 | B32: 3 חדרים | C32: 347 | D32: 1 | E32: 0 | H32: 2 | I32: 2 | J32: 2 | K32: 2 | L32: 2 | M32: 2 | N32: 2 | O32: 2 | P32: 2 | Q32: 2 | R32: 2 | S32: 2 | T32: 0
A33: 32 | B33: 5 חדרים | C33: 522 | D33: 1 | E33: 0 | H33: 2 | I33: 2 | J33: 2 | K33: 2 | L33: 2 | M33: 2 | N33: 2 | O33: 2 | P33: 2 | Q33: 2 | R33: 2 | S33: 2 | T33: 0
A34: 33 | B34: 5 חדרים | C34: 549 | D34: 1 | E34: 0 | H34: 2 | I34: 2 | J34: 2 | K34: 2 | L34: 2 | M34: 2 | N34: 2 | O34: 2 | P34: 2 | Q34: 2 | R34: 2 | S34: 2 | T34: 0
A35: 34 | B35: 5 חדרים | C35: 549 | D35: 1 | E35: 0 | H35: 2 | I35: 2 | J35: 2 | K35: 2 | L35: 2 | M35: 2 | N35: 2 | O35: 2 | P35: 2 | Q35: 2 | R35: 2 | S35: 2 | T35: 0
A36: 35 | B36: 4 חדרים | C36: 482 | D36: 0 | E36: 0
A37: 36 | B37: 3 חדרים | C37: 347 | D37: 1 | E37: 0 | H37: 2 | I37: 2 | J37: 2 | K37: 2 | L37: 2 | M37: 2 | N37: 2 | O37: 2 | P37: 2 | Q37: 2 | R37: 2 | S37: 2 | T37: 1 | U37: 1 | V37: 1 | W37: 1 | X37: 1 | Y37: 1 | Z37: 1 | AA37: 1 | AB37: 1 | AC37: 1
A38: 37 | B38: 3 חדרים | C38: 347 | D38: 1 | E38: 0 | H38: 2 | I38: 2 | J38: 2 | K38: 2 | L38: 2 | M38: 2 | N38: 2 | O38: 2 | P38: 2 | Q38: 2 | R38: 2 | S38: 2 | T38: 1 | U38: 1 | V38: 1 | W38: 1 | X38: 1 | Y38: 1 | Z38: 1 | AA38: 1 | AB38: 1 | AC38: 1
A39: 38 | B39: 5 חדרים | C39: 522 | D39: 1 | E39: 522 | H39: 2 | I39: 2 | J39: 2 | K39: 2 | L39: 2 | M39: 2 | N39: 2 | O39: 2 | P39: 2 | Q39: 1 | R39: 0 | S39: 0 | T39: 0
A40: 39 | B40: 5 חדרים | C40: 549 | D40: 1 | E40: 0 | H40: 2 | I40: 2 | J40: 2 | K40: 2 | L40: 2 | M40: 2 | N40: 2 | O40: 2 | P40: 2 | Q40: 2 | R40: 0 | S40: 0 | T40: 0
...

Sheet הגדרות
A1: יתרה בקופה (₪) | B1: 73729
A3: הערה: עדכן את היתרה הנוכחית בתא B1

Sheet חישובים
A1: חודש | B1: סה״כ צפוי | C1: שילמו (2) | D1: ממתינים (1) | E1: לא שילמו (0) | F1: סה״כ נגבה | G1: אחוז גבייה | H1: דירות פעילות | I1: הוצאות (₪)
A2: ינואר 25 | B2: =SUMIF(נתוני_תשלומים!D:D,1,נתוני_תשלומים!C:C) -> 34349 | C2: =SUMPRODUCT((נתוני_תשלומים!F2:F77=2)*(נתוני_תשלומים!D2:D77=1)) -> 0 | D2: =SUMPRODUCT((נתוני_תשלומים!F2:F77=1)*(נתוני_תשלומים!D2:D77=1)) -> 0 | E2: =H2-(C2+D2) -> 72 | F2: =SUMPRODUCT((נתוני_תשלומים!F2:F77=2)*(נתוני_תשלומים!D2:D77=1)*(נתוני_תשלומים!C2:C77)) -> 0 | G2: =IF(B2=0,0,F2/B2) -> 0 | H2: =COUNTIF(נתוני_תשלומים!D:D,1) -> 72 | I2: 0
A3: פברואר 25 | B3: =SUMIF(נתוני_תשלומים!D:D,1,נתוני_תשלומים!C:C) -> 34349 | C3: =SUMPRODUCT((נתוני_תשלומים!G2:G77=2)*(נתוני_תשלומים!D2:D77=1)) -> 0 | D3: =SUMPRODUCT((נתוני_תשלומים!G2:G77=1)*(נתוני_תשלומים!D2:D77=1)) -> 0 | E3: =H3-(C3+D3) -> 72 | F3: =SUMPRODUCT((נתוני_תשלומים!G2:G77=2)*(נתוני_תשלומים!D2:D77=1)*(נתוני_תשלומים!C2:C77)) -> 0 | G3: =IF(B3=0,0,F3/B3) -> 0 | H3: =COUNTIF(נתוני_תשלומים!D:D,1) -> 72 | I3: 0
A4: מרץ 25 | B4: =SUMIF(נתוני_תשלומים!D:D,1,נתוני_תשלומים!C:C) -> 34349 | C4: =SUMPRODUCT((נתוני_תשלומים!H2:H77=2)*(נתוני_תשלומים!D2:D77=1)) -> 71 | D4: =SUMPRODUCT((נתוני_תשלומים!H2:H77=1)*(נתוני_תשלומים!D2:D77=1)) -> 0 | E4: =H4-(C4+D4) -> 1 | F4: =SUMPRODUCT((נתוני_תשלומים!H2:H77=2)*(נתוני_תשלומים!D2:D77=1)*(נתוני_תשלומים!C2:C77)) -> 34002 | G4: =IF(B4=0,0,F4/B4) -> 0.98989781 | H4: =COUNTIF(נתוני_תשלומים!D:D,1) -> 72 | I4: 0
A5: אפריל 25 | B5: =SUMIF(נתוני_תשלומים!D:D,1,נתוני_תשלומים!C:C) -> 34349 | C5: =SUMPRODUCT((נתוני_תשלומים!I2:I77=2)*(נתוני_תשלומים!D2:D77=1)) -> 71 | D5: =SUMPRODUCT((נתוני_תשלומים!I2:I77=1)*(נתוני_תשלומים!D2:D77=1)) -> 0 | E5: =H5-(C5+D5) -> 1 | F5: =SUMPRODUCT((נתוני_תשלומים!I2:I77=2)*(נתוני_תשלומים!D2:D77=1)*(נתוני_תשלומים!C2:C77)) -> 34002 | G5: =IF(B5=0,0,F5/B5) -> 0.98989781 | H5: =COUNTIF(נתוני_תשלומים!D:D,1) -> 72 | I5: 0
A6: מאי 25 | B6: =SUMIF(נתוני_תשלומים!D:D,1,נתוני_תשלומים!C:C) -> 34349 | C6: =SUMPRODUCT((נתוני_תשלומים!J2:J77=2)*(נתוני_תשלומים!D2:D77=1)) -> 71 | D6: =SUMPRODUCT((נתוני_תשלומים!J2:J77=1)*(נתוני_תשלומים!D2:D77=1)) -> 0 | E6: =H6-(C6+D6) -> 1 | F6: =SUMPRODUCT((נתוני_תשלומים!J2:J77=2)*(נתוני_תשלומים!D2:D77=1)*(נתוני_תשלומים!C2:C77)) -> 34002 | G6: =IF(B6=0,0,F6/B6) -> 0.98989781 | H6: =COUNTIF(נתוני_תשלומים!D:D,1) -> 72 | I6: 0
A7: יוני 25 | B7: =SUMIF(נתוני_תשלומים!D:D,1,נתוני_תשלומים!C:C) -> 34349 | C7: =SUMPRODUCT((נתוני_תשלומים!K2:K77=2)*(נתוני_תשלומים!D2:D77=1)) -> 71 | D7: =SUMPRODUCT((נתוני_תשלומים!K2:K77=1)*(נתוני_תשלומים!D2:D77=1)) -> 0 | E7: =H7-(C7+D7) -> 1 | F7: =SUMPRODUCT((נתוני_תשלומים!K2:K77=2)*(נתוני_תשלומים!D2:D77=1)*(נתוני_תשלומים!C2:C77)) -> 34002 | G7: =IF(B7=0,0,F7/B7) -> 0.98989781 | H7: =COUNTIF(נתוני_תשלומים!D:D,1) -> 72 | I7: 0
A8: יולי 25 | B8: =SUMIF(נתוני_תשלומים!D:D,1,נתוני_תשלומים!C:C) -> 34349 | C8: =SUMPRODUCT((נתוני_תשלומים!L2:L77=2)*(נתוני_תשלומים!D2:D77=1)) -> 71 | D8: =SUMPRODUCT((נתוני_תשלומים!L2:L77=1)*(נתוני_תשלומים!D2:D77=1)) -> 0 | E8: =H8-(C8+D8) -> 1 | F8: =SUMPRODUCT((נתוני_תשלומים!L2:L77=2)*(נתוני_תשלומים!D2:D77=1)*(נתוני_תשלומים!C2:C77)) -> 34002 | G8: =IF(B8=0,0,F8/B8) -> 0.98989781 | H8: =COUNTIF(נתוני_תשלומים!D:D,1) -> 72 | I8: 0
A9: אוגוסט 25 | B9: =SUMIF(נתוני_תשלומים!D:D,1,נתוני_תשלומים!C:C) -> 34349 | C9: =SUMPRODUCT((נתוני_תשלומים!M2:M77=2)*(נתוני_תשלומים!D2:D77=1)) -> 71 | D9: =SUMPRODUCT((נתוני_תשלומים!M2:M77=1)*(נתוני_תשלומים!D2:D77=1)) -> 0 | E9: =H9-(C9+D9) -> 1 | F9: =SUMPRODUCT((נתוני_תשלומים!M2:M77=2)*(נתוני_תשלומים!D2:D77=1)*(נתוני_תשלומים!C2:C77)) -> 34002 | G9: =IF(B9=0,0,F9/B9) -> 0.98989781 | H9: =COUNTIF(נתוני_תשלומים!D:D,1) -> 72 | I9: 0
A10: ספטמבר 25 | B10: =SUMIF(נתוני_תשלומים!D:D,1,נתוני_תשלומים!C:C) -> 34349 | C10: =SUMPRODUCT((נתוני_תשלומים!N2:N77=2)*(נתוני_תשלומים!D2:D77=1)) -> 71 | D10: =SUMPRODUCT((נתוני_תשלומים!N2:N77=1)*(נתוני_תשלומים!D2:D77=1)) -> 0 | E10: =H10-(C10+D10) -> 1 | F10: =SUMPRODUCT((נתוני_תשלומים!N2:N77=2)*(נתוני_תשלומים!D2:D77=1)*(נתוני_תשלומים!C2:C77)) -> 34002 | G10: =IF(B10=0,0,F10/B10) -> 0.98989781 | H10: =COUNTIF(נתוני_תשלומים!D:D,1) -> 72 | I10: 0
A11: אוקטובר 25 | B11: =SUMIF(נתוני_תשלומים!D:D,1,נתוני_תשלומים!C:C) -> 34349 | C11: =SUMPRODUCT((נתוני_תשלומים!O2:O77=2)*(נתוני_תשלומים!D2:D77=1)) -> 70 | D11: =SUMPRODUCT((נתוני_תשלומים!O2:O77=1)*(נתוני_תשלומים!D2:D77=1)) -> 1 | E11: =H11-(C11+D11) -> 1 | F11: =SUMPRODUCT((נתוני_תשלומים!O2:O77=2)*(נתוני_תשלומים!D2:D77=1)*(נתוני_תשלומים!C2:C77)) -> 33453 | G11: =IF(B11=0,0,F11/B11) -> 0.97391482 | H11: =COUNTIF(נתוני_תשלומים!D:D,1) -> 72 | I11: 0
A12: נובמבר 25 | B12: =SUMIF(נתוני_תשלומים!D:D,1,נתוני_תשלומים!C:C) -> 34349 | C12: =SUMPRODUCT((נתוני_תשלומים!P2:P77=2)*(נתוני_תשלומים!D2:D77=1)) -> 69 | D12: =SUMPRODUCT((נתוני_תשלומים!P2:P77=1)*(נתוני_תשלומים!D2:D77=1)) -> 0 | E12: =H12-(C12+D12) -> 3 | F12: =SUMPRODUCT((נתוני_תשלומים!P2:P77=2)*(נתוני_תשלומים!D2:D77=1)*(נתוני_תשלומים!C2:C77)) -> 33101 | G12: =IF(B12=0,0,F12/B12) -> 0.96366706 | H12: =COUNTIF(נתוני_תשלומים!D:D,1) -> 72 | I12: 0
A13: דצמבר 25 | B13: =SUMIF(נתוני_תשלומים!D:D,1,נתוני_תשלומים!C:C) -> 34349 | C13: =SUMPRODUCT((נתוני_תשלומים!Q2:Q77=2)*(נתוני_תשלומים!D2:D77=1)) -> 65 | D13: =SUMPRODUCT((נתוני_תשלומים!Q2:Q77=1)*(נתוני_תשלומים!D2:D77=1)) -> 2 | E13: =H13-(C13+D13) -> 5 | F13: =SUMPRODUCT((נתוני_תשלומים!Q2:Q77=2)*(נתוני_תשלומים!D2:D77=1)*(נתוני_תשלומים!C2:C77)) -> 31228 | G13: =IF(B13=0,0,F13/B13) -> 0.90913855 | H13: =COUNTIF(נתוני_תשלומים!D:D,1) -> 72 | I13: 0
A14: ינואר 26 | B14: =SUMIF(נתוני_תשלומים!D:D,1,נתוני_תשלומים!C:C) -> 34349 | C14: =SUMPRODUCT((נתוני_תשלומים!R2:R77=2)*(נתוני_תשלומים!D2:D77=1)) -> 60 | D14: =SUMPRODUCT((נתוני_תשלומים!R2:R77=1)*(נתוני_תשלומים!D2:D77=1)) -> 1 | E14: =H14-(C14+D14) -> 11 | F14: =SUMPRODUCT((נתוני_תשלומים!R2:R77=2)*(נתוני_תשלומים!D2:D77=1)*(נתוני_תשלומים!C2:C77)) -> 28927 | G14: =IF(B14=0,0,F14/B14) -> 0.8421497 | H14: =COUNTIF(נתוני_תשלומים!D:D,1) -> 72 | I14: 0
A15: פברואר 26 | B15: =SUMIF(נתוני_תשלומים!D:D,1,נתוני_תשלומים!C:C) -> 34349 | C15: =SUMPRODUCT((נתוני_תשלומים!S2:S77=2)*(נתוני_תשלומים!D2:D77=1)) -> 59 | D15: =SUMPRODUCT((נתוני_תשלומים!S2:S77=1)*(נתוני_תשלומים!D2:D77=1)) -> 0 | E15: =H15-(C15+D15) -> 13 | F15: =SUMPRODUCT((נתוני_תשלומים!S2:S77=2)*(נתוני_תשלומים!D2:D77=1)*(נתוני_תשלומים!C2:C77)) -> 28580 | G15: =IF(B15=0,0,F15/B15) -> 0.83204751 | H15: =COUNTIF(נתוני_תשלומים!D:D,1) -> 72 | I15: 0
A16: מרץ 26 | B16: =SUMIF(נתוני_תשלומים!D:D,1,נתוני_תשלומים!C:C) -> 34349 | C16: =SUMPRODUCT((נתוני_תשלומים!T2:T77=2)*(נתוני_תשלומים!D2:D77=1)) -> 3 | D16: =SUMPRODUCT((נתוני_תשלומים!T2:T77=1)*(נתוני_תשלומים!D2:D77=1)) -> 22 | E16: =H16-(C16+D16) -> 47 | F16: =SUMPRODUCT((נתוני_תשלומים!T2:T77=2)*(נתוני_תשלומים!D2:D77=1)*(נתוני_תשלומים!C2:C77)) -> 1311 | G16: =IF(B16=0,0,F16/B16) -> 0.03816705 | H16: =COUNTIF(נתוני_תשלומים!D:D,1) -> 72 | I16: 0
A17: אפריל 26 | B17: =SUMIF(נתוני_תשלומים!D:D,1,נתוני_תשלומים!C:C) -> 34349 | C17: =SUMPRODUCT((נתוני_תשלומים!U2:U77=2)*(נתוני_תשלומים!D2:D77=1)) -> 0 | D17: =SUMPRODUCT((נתוני_תשלומים!U2:U77=1)*(נתוני_תשלומים!D2:D77=1)) -> 22 | E17: =H17-(C17+D17) -> 50 | F17: =SUMPRODUCT((נתוני_תשלומים!U2:U77=2)*(נתוני_תשלומים!D2:D77=1)*(נתוני_תשלומים!C2:C77)) -> 0 | G17: =IF(B17=0,0,F17/B17) -> 0 | H17: =COUNTIF(נתוני_תשלומים!D:D,1) -> 72 | I17: 0
A18: מאי 26 | B18: =SUMIF(נתוני_תשלומים!D:D,1,נתוני_תשלומים!C:C) -> 34349 | C18: =SUMPRODUCT((נתוני_תשלומים!V2:V77=2)*(נתוני_תשלומים!D2:D77=1)) -> 0 | D18: =SUMPRODUCT((נתוני_תשלומים!V2:V77=1)*(נתוני_תשלומים!D2:D77=1)) -> 22 | E18: =H18-(C18+D18) -> 50 | F18: =SUMPRODUCT((נתוני_תשלומים!V2:V77=2)*(נתוני_תשלומים!D2:D77=1)*(נתוני_תשלומים!C2:C77)) -> 0 | G18: =IF(B18=0,0,F18/B18) -> 0 | H18: =COUNTIF(נתוני_תשלומים!D:D,1) -> 72 | I18: 0
A19: יוני 26 | B19: =SUMIF(נתוני_תשלומים!D:D,1,נתוני_תשלומים!C:C) -> 34349 | C19: =SUMPRODUCT((נתוני_תשלומים!W2:W77=2)*(נתוני_תשלומים!D2:D77=1)) -> 0 | D19: =SUMPRODUCT((נתוני_תשלומים!W2:W77=1)*(נתוני_תשלומים!D2:D77=1)) -> 22 | E19: =H19-(C19+D19) -> 50 | F19: =SUMPRODUCT((נתוני_תשלומים!W2:W77=2)*(נתוני_תשלומים!D2:D77=1)*(נתוני_תשלומים!C2:C77)) -> 0 | G19: =IF(B19=0,0,F19/B19) -> 0 | H19: =COUNTIF(נתוני_תשלומים!D:D,1) -> 72 | I19: 0
A20: יולי 26 | B20: =SUMIF(נתוני_תשלומים!D:D,1,נתוני_תשלומים!C:C) -> 34349 | C20: =SUMPRODUCT((נתוני_תשלומים!X2:X77=2)*(נתוני_תשלומים!D2:D77=1)) -> 0 | D20: =SUMPRODUCT((נתוני_תשלומים!X2:X77=1)*(נתוני_תשלומים!D2:D77=1)) -> 21 | E20: =H20-(C20+D20) -> 51 | F20: =SUMPRODUCT((נתוני_תשלומים!X2:X77=2)*(נתוני_תשלומים!D2:D77=1)*(נתוני_תשלומים!C2:C77)) -> 0 | G20: =IF(B20=0,0,F20/B20) -> 0 | H20: =COUNTIF(נתוני_תשלומים!D:D,1) -> 72 | I20: 0
A21: אוגוסט 26 | B21: =SUMIF(נתוני_תשלומים!D:D,1,נתוני_תשלומים!C:C) -> 34349 | C21: =SUMPRODUCT((נתוני_תשלומים!Y2:Y77=2)*(נתוני_תשלומים!D2:D77=1)) -> 0 | D21: =SUMPRODUCT((נתוני_תשלומים!Y2:Y77=1)*(נתוני_תשלומים!D2:D77=1)) -> 21 | E21: =H21-(C21+D21) -> 51 | F21: =SUMPRODUCT((נתוני_תשלומים!Y2:Y77=2)*(נתוני_תשלומים!D2:D77=1)*(נתוני_תשלומים!C2:C77)) -> 0 | G21: =IF(B21=0,0,F21/B21) -> 0 | H21: =COUNTIF(נתוני_תשלומים!D:D,1) -> 72 | I21: 0
A22: ספטמבר 26 | B22: =SUMIF(נתוני_תשלומים!D:D,1,נתוני_תשלומים!C:C) -> 34349 | C22: =SUMPRODUCT((נתוני_תשלומים!Z2:Z77=2)*(נתוני_תשלומים!D2:D77=1)) -> 0 | D22: =SUMPRODUCT((נתוני_תשלומים!Z2:Z77=1)*(נתוני_תשלומים!D2:D77=1)) -> 21 | E22: =H22-(C22+D22) -> 51 | F22: =SUMPRODUCT((נתוני_תשלומים!Z2:Z77=2)*(נתוני_תשלומים!D2:D77=1)*(נתוני_תשלומים!C2:C77)) -> 0 | G22: =IF(B22=0,0,F22/B22) -> 0 | H22: =COUNTIF(נתוני_תשלומים!D:D,1) -> 72 | I22: 0
A23: אוקטובר 26 | B23: =SUMIF(נתוני_תשלומים!D:D,1,נתוני_תשלומים!C:C) -> 34349 | C23: =SUMPRODUCT((נתוני_תשלומים!AA2:AA77=2)*(נתוני_תשלומים!D2:D77=1)) -> 0 | D23: =SUMPRODUCT((נתוני_תשלומים!AA2:AA77=1)*(נתוני_תשלומים!D2:D77=1)) -> 20 | E23: =H23-(C23+D23) -> 52 | F23: =SUMPRODUCT((נתוני_תשלומים!AA2:AA77=2)*(נתוני_תשלומים!D2:D77=1)*(נתוני_תשלומים!C2:C77)) -> 0 | G23: =IF(B23=0,0,F23/B23) -> 0 | H23: =COUNTIF(נתוני_תשלומים!D:D,1) -> 72 | I23: 0
A24: נובמבר 26 | B24: =SUMIF(נתוני_תשלומים!D:D,1,נתוני_תשלומים!C:C) -> 34349 | C24: =SUMPRODUCT((נתוני_תשלומים!AB2:AB77=2)*(נתוני_תשלומים!D2:D77=1)) -> 0 | D24: =SUMPRODUCT((נתוני_תשלומים!AB2:AB77=1)*(נתוני_תשלומים!D2:D77=1)) -> 21 | E24: =H24-(C24+D24) -> 51 | F24: =SUMPRODUCT((נתוני_תשלומים!AB2:AB77=2)*(נתוני_תשלומים!D2:D77=1)*(נתוני_תשלומים!C2:C77)) -> 0 | G24: =IF(B24=0,0,F24/B24) -> 0 | H24: =COUNTIF(נתוני_תשלומים!D:D,1) -> 72 | I24: 0
A25: דצמבר 26 | B25: =SUMIF(נתוני_תשלומים!D:D,1,נתוני_תשלומים!C:C) -> 34349 | C25: =SUMPRODUCT((נתוני_תשלומים!AC2:AC77=2)*(נתוני_תשלומים!D2:D77=1)) -> 0 | D25: =SUMPRODUCT((נתוני_תשלומים!AC2:AC77=1)*(נתוני_תשלומים!D2:D77=1)) -> 21 | E25: =H25-(C25+D25) -> 51 | F25: =SUMPRODUCT((נתוני_תשלומים!AC2:AC77=2)*(נתוני_תשלומים!D2:D77=1)*(נתוני_תשלומים!C2:C77)) -> 0 | G25: =IF(B25=0,0,F25/B25) -> 0 | H25: =COUNTIF(נתוני_תשלומים!D:D,1) -> 72 | I25: 0
A26: סה״כ חובות נוכחי | B26: =SUM(נתוני_תשלומים!E:E) -> 9213
A28: הוצאות חודשיות (מתעדכן אוטומטית)
A29: חודש | B29: הוצאות (₪)
A30: ינואר 25 | B30: =הוצאות!B10 -> 36924
A31: פברואר 25 | B31: =הוצאות!C10 -> 25491
A32: מרץ 25 | B32: =הוצאות!D10 -> 26611
A33: אפריל 25 | B33: =הוצאות!E10 -> 25278
A34: מאי 25 | B34: =הוצאות!F10 -> 23113
A35: יוני 25 | B35: =הוצאות!G10 -> 26598
A36: יולי 25 | B36: =הוצאות!H10 -> 68424
A37: אוגוסט 25 | B37: =הוצאות!I10 -> 26657
A38: ספטמבר 25 | B38: =הוצאות!J10 -> 37574
A39: אוקטובר 25 | B39: =הוצאות!K10 -> 21122
A40: נובמבר 25 | B40: =הוצאות!L10 -> 40081
A41: דצמבר 25 | B41: =הוצאות!M10 -> 31861
...

Sheet הוראות_שימוש
A1: הוראות שימוש - מערכת מעקב תשלומי ועד בית
A3: סטטוסי תשלום:
A4: 0 או ריק - לא שולם
A5: 1 - צ׳ק הועבר לפרעון (ממתין)
A6: 2 - שולם במלואו (סטטוס סופי)
A8: עמודת "פעיל":
A9: 1 - דירה פעילה (משלמת ועד)
A10: 0 - דירה לא פעילה (לא צריכה לשלם)
A12: עמודת "חוב עד 12/25":
A13: הכנס את סכום החוב שהיה לדירה עד סוף 2025
A14: זה כולל את כל חובות 2025 ומה שלפניו
A15: ברירת מחדל: 0
... A26: חוב עד 12/25 + חודשי 2026 שעברו (לא החודש הנוכחי)

Sheet הוצאות
A1: קטגוריה | B1: ינואר 25 | C1: פברואר 25 | D1: מרץ 25 | E1: אפריל 25 | F1: מאי 25 | G1: יוני 25 | H1: יולי 25 | I1: אוגוסט 25 | J1: ספטמבר 25 | K1: אוקטובר 25 | L1: נובמבר 25 | M1: דצמבר 25 | N1: ינואר 26 | O1: פברואר 26 | P1: מרץ 26 | Q1: אפריל 26 | R1: מאי 26 | S1: יוני 26 | T1: יולי 26 | U1: אוגוסט 26 | V1: ספטמבר 26 | W1: אוקטובר 26 | X1: נובמבר 26 | Y1: דצמבר 26
A2: חברת אחזקה | B2: 14350 | C2: 14350 | D2: 14350 | E2: 14350 | F2: 14350 | G2: 14350 | H2: 14545 | I2: 14295 | J2: 15298 | K2: 14000 | L2: 14000 | M2: 14472 | N2: 15092 | O2: 15357 | P2: 0 | Q2: 0 | R2: 0 | S2: 0 | T2: 0 | U2: 0 | V2: 0 | W2: 0 | X2: 0 | Y2: 0
A3: מעליות | B3: 5193 | C3: 3701 | D3: 3701 | E3: 3701 | F3: 3701 | G3: 3701 | H3: 3701 | I3: 3701 | J3: 3701 | K3: 3701 | L3: 3701 | M3: 3701 | N3: 9691 | O3: 3701 | P3: 0 | Q3: 0 | R3: 0 | S3: 0 | T3: 0 | U3: 0 | V3: 0 | W3: 0 | X3: 0 | Y3: 0
A4: בזק | B4: 56 | C4: 57 | D4: 53 | E4: 55 | F4: 61 | G4: 60 | H4: 56 | I4: 56 | J4: 55 | K4: 59 | L4: 61 | M4: 62 | N4: 62 | O4: 62 | P4: 0 | Q4: 0 | R4: 0 | S4: 0 | T4: 0 | U4: 0 | V4: 0 | W4: 0 | X4: 0 | Y4: 0
A5: חשמל (כולל חניון) | B5: 5733 | C5: 4257 | D5: 6114 | E5: 6185 | F5: 3516 | G5: 7745 | H5: 9168 | I5: 8453 | J5: 12356 | K5: 2880 | L5: 17068 | M5: 7034 | N5: 3811 | O5: 6975 | P5: 0 | Q5: 0 | R5: 0 | S5: 0 | T5: 0 | U5: 0 | V5: 0 | W5: 0 | X5: 0 | Y5: 0
A6: מסכים | B6: 129 | C6: 154 | D6: 150 | E6: 152 | F6: 152 | G6: 152 | H6: 152 | I6: 152 | J6: 152 | K6: 152 | L6: 152 | M6: 152 | N6: 152 | O6: 152 | P6: 0 | Q6: 0 | R6: 0 | S6: 0 | T6: 0 | U6: 0 | V6: 0 | W6: 0 | X6: 0 | Y6: 0
A7: ביטוח | B7: 0 | C7: 0 | D7: 0 | E7: 0 | F7: 0 | G7: 0 | H7: 15466 | I7: 0 | J7: 0 | K7: 0 | L7: 0 | M7: 0 | N7: 0 | O7: 0 | P7: 0 | Q7: 0 | R7: 0 | S7: 0 | T7: 0 | U7: 0 | V7: 0 | W7: 0 | X7: 0 | Y7: 0
A8: טיפול בתקלות | B8: 11463 | C8: 2972 | D8: 2243 | E8: 0 | F8: 1333 | G8: 590 | H8: 5336 | I8: 0 | J8: 4012 | K8: 330 | L8: 3500 | M8: 6440 | N8: 2340 | O8: 0 | P8: 0 | Q8: 0 | R8: 0 | S8: 0 | T8: 0 | U8: 0 | V8: 0 | W8: 0 | X8: 0 | Y8: 0
A9: הוצאות שונות | B9: 0 | C9: 0 | D9: 0 | E9: 835 | F9: 0 | G9: 0 | H9: 20000 | I9: 0 | J9: 2000 | K9: 0 | L9: 1599 | M9: 0 | N9: 0 | O9: 0 | P9: 0 | Q9: 0 | R9: 0 | S9: 0 | T9: 0 | U9: 0 | V9: 0 | W9: 0 | X9: 0 | Y9: 0
A10: סה״כ חודשי | B10: =SUM(B2:B9) -> 36924 | C10: =SUM(C2:C9) -> 25491 | D10: =SUM(D2:D9) -> 26611 | E10: =SUM(E2:E9) -> 25278 | F10: =SUM(F2:F9) -> 23113 | G10: =SUM(G2:G9) -> 26598 | H10: =SUM(H2:H9) -> 68424 | I10: =SUM(I2:I9) -> 26657 | ... Y10: =SUM(Y2:Y9) -> 0
